# 2.5 코틀린 예외 처리

## 2.5.0 Intro

```kotlin
val percentage =
	if (num in 0..100)
		number
	else
		throw IllegalArgumentException(
			"A percentage value must be between 0 and 100: $number")
```

- 코틀린 예외 처리는 자바나 다른 언어의 예외 처리와 비슷하다
- 함수는 정상적으로 종료할 수 있지만 오류가 발생하면 예외를 throw할 수 있다
- 함수를 호출하는 쪽에서는 그 예외를 잡아 처리할 수 있다
- 발생한 예외를 함수 호출 단에서 처리하지 않으면 함수 호출 스택을 거슬러 올라가면서 예외를 처리하는 부분이 나올 때까지 예외를 다시 던진다
- 예외 인스턴스도 **new 키워드를 쓰지 않는다**
- 코틀린의 throw는 식이므로 다른 식에 포함될 수 있다

## 2.5.1 try, catch, finally

```kotlin
fun main() {
  val reader1 = BufferedReader(StringReader("123"))
  println(readNumber(reader)) // 123 출력

	val reader1 = BufferedReader(StringReader("hello"))
    println(readNumber(reader)) // null 출력
}

fun readNumber(reader: BufferedReader): Int? {
	try {
		val line = reader.readLine()
		return Integer.parseInt(line)
	}
	catch(e: NumberFormatException) {
		return null
	}
	finally {
		reader.close()
	}
}
```

- try{}에서 실행한 코드중에 오류가 발생하면 catch{}에서 해당 에러에 대해 오류 처리
- finally{}는 try{}가 정상적으로 실행이 되든, 에러가 발생해서 catch{}를 실행해 오류 처리를 하든 무조건 실행되는 부분으로 생략해도 됨
- 자바와 큰 차이는 **throws절이 없다**는 점이다
    - 자바에서는 체크 예외를 throws 해줘야 하지만 코틀린에서는 체크 예외와 언체크 예외를 구분하지 않음
- 예외 타입은 :의 오른쪽에 쓴다

## 2.5.2 try를 식으로 사용

```kotlin
fun main() {
  val reader = BufferedReader(StringReader("hello"))
  readNumber(reader) // 아무것도 출력되지 않음
}

fun readNumber(reader: BufferedReader) {
	val number = try {
		Integer.parseInt(reader.readLine())
	} catch(e: NumberFormatException) {
		return
	}
	println(number)
}
```

- try는 if나 when과 마찬가지로 식이다. 따라서 try의 값을 변수에 대입할 수 있다.
- 다만, 반드시 중괄호 {} 로 감싸주어야 한다.
- 위의 코드에서 Exception이 발생하며 catch로 이동하게 되고 해당 블록에서 return을 하고 있으므로 그 아래 코드는 실행되지 않는다.
    - 따라서 위의 예제를 아래처럼 바꿔야 한다

```kotlin
fun main() {
  val reader = BufferedReader(StringReader("hello"))
  readNumber(reader) // null 출력
}

fun readNumber(reader: BufferedReader) {
	val number = try {
		Integer.parseInt(reader.readLine())
	} catch(e: NumberFormatException) {
		null
	}
	println(number)
}
```